Workbook

Sheet Costing Sheet
A1: Bangladesh Industrial Technical Assistance Centre
A2: 116 Kha, Tejgaon I/A.
A3: Dhaka-1208
A4: Job Estimating/Costing
A6: Company Name:
A7: Job Name:
A8: Job Quantity
A9: Job/Part No: | C9: 1
A10: Actual Size:
A11: Materials Size:
A13: A. Material Cost
A14: Sl. No. | B14: Material Name | C14: Quantity (KG) | E14: Rate (TK/KG) | F14: Amount (TK) | G14: Remarks
A15: 01 | C15: =SUMIFS('Weight Cal'!H$6:H$37,'Weight Cal'!B$6:B$37,'Costing Sheet'!B15) -> 0 | E15: =SUMIFS('Materials Rate'!C$9:C$70,'Materials Rate'!B$9:B$70,'Costing Sheet'!B15) -> 0 | F15: =E15*C15 -> 0
A16: 02 | C16: =SUMIFS('Weight Cal'!H$6:H$37,'Weight Cal'!B$6:B$37,'Costing Sheet'!B16) -> 0 | E16: =SUMIFS('Materials Rate'!C$9:C$70,'Materials Rate'!B$9:B$70,'Costing Sheet'!B16) -> 0 | F16: =E16*C16 -> 0
A17: 03 | C17: =SUMIFS('Weight Cal'!H$6:H$37,'Weight Cal'!B$6:B$37,'Costing Sheet'!B17) -> 0 | E17: =SUMIFS('Materials Rate'!C$9:C$70,'Materials Rate'!B$9:B$70,'Costing Sheet'!B17) -> 0 | F17: =E17*C17 -> 0
A18: 04 | C18: =SUMIFS('Weight Cal'!H$6:H$37,'Weight Cal'!B$6:B$37,'Costing Sheet'!B18) -> 0 | E18: =SUMIFS('Materials Rate'!C$9:C$70,'Materials Rate'!B$9:B$70,'Costing Sheet'!B18) -> 0 | F18: =E18*C18 -> 0
A19: 05 | C19: =SUMIFS('Weight Cal'!H$6:H$37,'Weight Cal'!B$6:B$37,'Costing Sheet'!B19) -> 0 | E19: =SUMIFS('Materials Rate'!C$9:C$70,'Materials Rate'!B$9:B$70,'Costing Sheet'!B19) -> 0 | F19: =E19*C19 -> 0
A20: Sub-Total | C20: =SUM(C15:C19) -> 0 | F20: =SUM(F15:F19) -> 0
A21: B. Machining Cost
A22: Sl. No. | B22: Operation Name | C22: Quantity (Time) | E22: Rate (TK) | F22: Amount (TK) | G22: Remarks
C23: Hour | E23: TK/Hour
A24: 01 | E24: =SUMIFS(Machining!$D8:D$71,Machining!B$8:B$71,'Costing Sheet'!B24) -> 0 | F24: =E24*C24 -> 0
A25: 02 | E25: =SUMIFS(Machining!D$8:D$71,Machining!B$8:B$71,'Costing Sheet'!B25) -> 0 | F25: =E25*C25 -> 0
A26: 03 | E26: =SUMIFS(Machining!D$8:D$71,Machining!B$8:B$71,'Costing Sheet'!B26) -> 0 | F26: =E26*C26 -> 0
A27: 04 | E27: =SUMIFS(Machining!D$8:D$71,Machining!B$8:B$71,'Costing Sheet'!B27) -> 0 | F27: =E27*C27 -> 0
A28: 05 | E28: =SUMIFS(Machining!D$8:D$71,Machining!B$8:B$71,'Costing Sheet'!B28) -> 0 | F28: =E28*C28 -> 0
A29: 06 | E29: =SUMIFS(Machining!D$8:D$71,Machining!B$8:B$71,'Costing Sheet'!B29) -> 0 | F29: =E29*C29 -> 0
A30: 07 | E30: =SUMIFS(Machining!D$8:D$71,Machining!B$8:B$71,'Costing Sheet'!B30) -> 0 | F30: =E30*C30 -> 0
A31: 08 | E31: =SUMIFS(Machining!D$8:D$71,Machining!B$8:B$71,'Costing Sheet'!B31) -> 0 | F31: =E31*C31 -> 0
A32: Sub-Total | C32: =SUM(C24:D30) -> 0 | F32: =SUM(F24:F31) -> 0
A33: C. Surface Treatment Cost
A34: Sl. No. | B34: Operation Name | C34: Quantity (Time) | E34: Rate (TK) | F34: Amount (TK) | G34: Remarks
C35: In³ | E35: TK/In³
A36: 01 | C36: =SUMIFS('HT Cal'!F$6:F$37,'HT Cal'!B$6:B$37,'Costing Sheet'!B36) -> 0 | E36: =SUMIFS('Materials Rate'!C$72:C$79,'Materials Rate'!B$72:B$79,'Costing Sheet'!B36) -> 0 | F36: =E36*C36 -> 0
A37: 02 | C37: =SUMIFS('HT Cal'!F$6:F$37,'HT Cal'!B$6:B$37,'Costing Sheet'!B37) -> 0 | E37: =SUMIFS('Materials Rate'!C$72:C$79,'Materials Rate'!B$72:B$79,'Costing Sheet'!B37) -> 0 | F37: =E37*C37 -> 0
A38: 03 | C38: =SUMIFS('HT Cal'!F$6:F$37,'HT Cal'!B$6:B$37,'Costing Sheet'!B38) -> 0 | E38: =SUMIFS('Materials Rate'!C$72:C$79,'Materials Rate'!B$72:B$79,'Costing Sheet'!B38) -> 0 | F38: =E38*C38 -> 0
A39: Sub-Total | C39: =SUM(C36:C38) -> 0 | F39: =SUM(F36:F38) -> 0
A40: D. Other Parts
A41: Sl. No. | B41: Operation Name | C41: Quantity (PCs) | E41: Rate (TK) | F41: Amount (TK) | G41: Remarks
E42: TK/PCs
...

Sheet HT Cal
A1: Area Volume and Weight Calculation Sheet
A3: 1. Rectangular Job
A5: Sl. No. | B5: Material | C5: Length (M) | D5: Width (M) | E5: Height (M) | F5: Volume (In³) | G5: Density (kg/In³) | H5: Weight (KG)
A6: 1 | C6: =SUMIFS('HT Size'!H$7:H$11,'HT Size'!B$7:B$11,'HT Cal'!B6) -> 0 | D6: =SUMIFS('HT Size'!M$7:M$11,'HT Size'!B7:B11,'HT Cal'!B6) -> 0 | E6: =SUMIFS('HT Size'!R$7:R$11,'HT Size'!B$7:B$11,'HT Cal'!B6) -> 0 | F6: =E6*D6*C6 -> 0 | G6: =SUMIFS('Materials Rate'!E$72:E$79,'Materials Rate'!B$72:B$79,'HT Cal'!B6) -> 0 | H6: =G6*F6 -> 0
A7: 2 | C7: =SUMIFS('Input Size'!H$7:H$11,'Input Size'!B$7:B$11,'HT Cal'!B7) -> 0 | D7: =SUMIFS('Input Size'!M$7:M$11,'Input Size'!B$7:B$11,'HT Cal'!B7) -> 0 | E7: =SUMIFS('Input Size'!R$7:R$11,'Input Size'!B$7:B$11,'HT Cal'!B7) -> 0 | F7: =E7*D7*C7 -> 0 | G7: =SUMIFS('Materials Rate'!E$72:E$79,'Materials Rate'!B$72:B$79,'HT Cal'!B7) -> 0 | H7: =G7*F7 -> 0
A8: 3 | C8: =SUMIFS('Input Size'!H$7:H$11,'Input Size'!B$7:B$11,'HT Cal'!B8) -> 0 | D8: =SUMIFS('Input Size'!M$7:M$11,'Input Size'!B$7:B$11,'HT Cal'!B8) -> 0 | E8: =SUMIFS('Input Size'!R$7:R$11,'Input Size'!B$7:B$11,'HT Cal'!B8) -> 0 | F8: =E8*D8*C8 -> 0 | G8: =SUMIFS('Materials Rate'!E$72:E$79,'Materials Rate'!B$72:B$79,'HT Cal'!B8) -> 0 | H8: =G8*F8 -> 0
A9: 4 | C9: =SUMIFS('Input Size'!H$7:H$11,'Input Size'!B$7:B$11,'HT Cal'!B9) -> 0 | D9: =SUMIFS('Input Size'!M$7:M$11,'Input Size'!B$7:B$11,'HT Cal'!B9) -> 0 | E9: =SUMIFS('Input Size'!R$7:R$11,'Input Size'!B$7:B$11,'HT Cal'!B9) -> 0 | F9: =E9*D9*C9 -> 0 | G9: =SUMIFS('Materials Rate'!E$72:E$79,'Materials Rate'!B$72:B$79,'HT Cal'!B9) -> 0 | H9: =G9*F9 -> 0
A10: 5 | C10: =SUMIFS('Input Size'!H$7:H$11,'Input Size'!B$7:B$11,'HT Cal'!B10) -> 0 | D10: =SUMIFS('Input Size'!M$7:M$11,'Input Size'!B$7:B$11,'HT Cal'!B10) -> 0 | E10: =SUMIFS('Input Size'!R$7:R$11,'Input Size'!B$7:B$11,'HT Cal'!B10) -> 0 | F10: =E10*D10*C10 -> 0 | G10: =SUMIFS('Materials Rate'!E$72:E$79,'Materials Rate'!B$72:B$79,'HT Cal'!B10) -> 0 | H10: =G10*F10 -> 0
A12: 2. Square Job
A14: Sl. No. | B14: Material | C14: Side (M) | D14: Height (M) | F14: Volume (In³) | G14: Density (kg/In³) | H14: Weight
A15: 1 | C15: =SUMIFS('HT Size'!H$18:H$22,'HT Size'!B$18:B$22,'HT Cal'!B15) -> 0 | D15: =SUMIFS('HT Size'!M$18:M$22,'HT Size'!B$18:B$22,'HT Cal'!B15) -> 0 | F15: =C15*D15 -> 0 | G15: =SUMIFS('Materials Rate'!E$72:E$79,'Materials Rate'!B$72:B$79,'HT Cal'!B15) -> 0 | H15: =F15*G15 -> 0
A16: 2 | C16: =SUMIFS('HT Size'!H$18:H$22,'HT Size'!B$18:B$22,'HT Cal'!B16) -> 0 | D16: =SUMIFS('HT Size'!M$18:M$22,'HT Size'!B$18:B$22,'HT Cal'!B16) -> 0 | F16: =C16*D16 -> 0 | G16: =SUMIFS('Materials Rate'!E$72:E$79,'Materials Rate'!B$72:B$79,'HT Cal'!B16) -> 0 | H16: =F16*G16 -> 0
A17: 3 | C17: =SUMIFS('HT Size'!H$18:H$22,'HT Size'!B$18:B$22,'HT Cal'!B17) -> 0 | D17: =SUMIFS('HT Size'!M$18:M$22,'HT Size'!B$18:B$22,'HT Cal'!B17) -> 0 | F17: =C17*D17 -> 0 | G17: =SUMIFS('Materials Rate'!E$72:E$79,'Materials Rate'!B$72:B$79,'HT Cal'!B17) -> 0 | H17: =F17*G17 -> 0
A18: 4 | C18: =SUMIFS('HT Size'!H$18:H$22,'HT Size'!B$18:B$22,'HT Cal'!B18) -> 0 | D18: =SUMIFS('HT Size'!M$18:M$22,'HT Size'!B$18:B$22,'HT Cal'!B18) -> 0 | F18: =C18*D18 -> 0 | G18: =SUMIFS('Materials Rate'!E$72:E$79,'Materials Rate'!B$72:B$79,'HT Cal'!B18) -> 0 | H18: =F18*G18 -> 0
A19: 5 | C19: =SUMIFS('HT Size'!H$18:H$22,'HT Size'!B$18:B$22,'HT Cal'!B19) -> 0 | D19: =SUMIFS('Input Size'!M$18:M$22,'Input Size'!B$18:B$22,'HT Cal'!B19) -> 0 | E19: =C19*C19*D19 -> 0 | F19: =SUMIFS(Density!C$9:C$69,Density!B$9:B$69,'HT Cal'!B19) -> 0 | G19: =SUMIFS('Materials Rate'!E$72:E$79,'Materials Rate'!B$72:B$79,'HT Cal'!B19) -> 0 | H19: =F19*G19 -> 0
A21: 3. Cylindrical Job
A23: Sl. No. | B23: Material | C23: Length (M) | D23: DIA (M) | F23: Volume (In³) | G23: Density (kg/In³) | H23: Weight
A24: 1 | C24: =SUMIFS('HT Size'!H$29:H$33,'HT Size'!B$29:B$33,'HT Cal'!B24) -> 0 | D24: =SUMIFS('HT Size'!M$29:M$33,'HT Size'!B$29:B$33,'HT Cal'!B24) -> 0 | F24: =((PI()*(D24*D24)/4)*C24) -> 0 | G24: =SUMIFS('Materials Rate'!E$72:E$79,'Materials Rate'!B$72:B$79,'HT Cal'!B24) -> 0 | H24: =F24*G24 -> 0
A25: 2 | C25: =SUMIFS('HT Size'!H$29:H$33,'HT Size'!B$29:B$33,'HT Cal'!B25) -> 0 | D25: =SUMIFS('HT Size'!M$29:M$33,'HT Size'!B$29:B$33,'HT Cal'!B25) -> 0 | F25: =((PI()*(D25*D25)/4)*C25) -> 0 | G25: =SUMIFS('Materials Rate'!E$72:E$79,'Materials Rate'!B$72:B$79,'HT Cal'!B25) -> 0 | H25: =F25*G25 -> 0
A26: 3 | C26: =SUMIFS('HT Size'!H$29:H$33,'HT Size'!B$29:B$33,'HT Cal'!B26) -> 0 | D26: =SUMIFS('HT Size'!M$29:M$33,'HT Size'!B$29:B$33,'HT Cal'!B26) -> 0 | F26: =((PI()*(D26*D26)/4)*C26) -> 0 | G26: =SUMIFS('Materials Rate'!E$72:E$79,'Materials Rate'!B$72:B$79,'HT Cal'!B26) -> 0 | H26: =F26*G26 -> 0
A27: 4 | C27: =SUMIFS('HT Size'!H$29:H$33,'HT Size'!B$29:B$33,'HT Cal'!B27) -> 0 | D27: =SUMIFS('HT Size'!M$29:M$33,'HT Size'!B$29:B$33,'HT Cal'!B27) -> 0 | F27: =((PI()*(D27*D27)/4)*C27) -> 0 | G27: =SUMIFS('Materials Rate'!E$72:E$79,'Materials Rate'!B$72:B$79,'HT Cal'!B27) -> 0 | H27: =F27*G27 -> 0
A28: 5 | C28: =SUMIFS('HT Size'!H$29:H$33,'HT Size'!B$29:B$33,'HT Cal'!B28) -> 0 | D28: =SUMIFS('HT Size'!M$29:M$33,'HT Size'!B$29:B$33,'HT Cal'!B28) -> 0 | F28: =((PI()*(D28*D28)/4)*C28) -> 0 | G28: =SUMIFS('Materials Rate'!E$72:E$79,'Materials Rate'!B$72:B$79,'HT Cal'!B28) -> 0 | H28: =F28*G28 -> 0
A30: 4. Cylindrical Hollow Job
A32: Sl. No. | B32: Material | C32: Length (M) | D32: DIA-D (M) | E32: DIA-d (M) | F32: Volume (In³) | G32: Density (kg/In³ | H32: Weight
A33: 1 | C33: =SUMIFS('HT Size'!H$40:H$44,'HT Size'!B$40:B$44,'HT Cal'!B33) -> 0 | D33: =SUMIFS('HT Size'!M$40:M$44,'HT Size'!B$40:B$44,'HT Cal'!B33) -> 0 | E33: =SUMIFS('HT Size'!R$40:R$44,'HT Size'!B$40:B$44,'HT Cal'!B33) -> 0 | F33: =((PI()*((D33*D33)-(E33*E33)))/4)*C33 -> 0 | G33: =SUMIFS('Materials Rate'!E$72:E$79,'Materials Rate'!B$72:B$79,'HT Cal'!B33) -> 0 | H33: =G33*F33 -> 0
A34: 2 | C34: =SUMIFS('HT Size'!H$40:H$44,'HT Size'!B$40:B$44,'HT Cal'!B34) -> 0 | D34: =SUMIFS('HT Size'!M$40:M$44,'HT Size'!B$40:B$44,'HT Cal'!B34) -> 0 | E34: =SUMIFS('HT Size'!R$40:R$44,'HT Size'!B$40:B$44,'HT Cal'!B34) -> 0 | F34: =((PI()*((D34*D34)-(E34*E34)))/4)*C34 -> 0 | G34: =SUMIFS('Materials Rate'!E$72:E$79,'Materials Rate'!B$72:B$79,'HT Cal'!B34) -> 0 | H34: =G34*F34 -> 0
A35: 3 | C35: =SUMIFS('HT Size'!H$40:H$44,'HT Size'!B$40:B$44,'HT Cal'!B35) -> 0 | D35: =SUMIFS('HT Size'!M$40:M$44,'HT Size'!B$40:B$44,'HT Cal'!B35) -> 0 | E35: =SUMIFS('HT Size'!R$40:R$44,'HT Size'!B$40:B$44,'HT Cal'!B35) -> 0 | F35: =((PI()*((D35*D35)-(E35*E35)))/4)*C35 -> 0 | G35: =SUMIFS('Materials Rate'!E$72:E$79,'Materials Rate'!B$72:B$79,'HT Cal'!B35) -> 0 | H35: =G35*F35 -> 0
A36: 4 | C36: =SUMIFS('HT Size'!H$40:H$44,'HT Size'!B$40:B$44,'HT Cal'!B36) -> 0 | D36: =SUMIFS('HT Size'!M$40:M$44,'HT Size'!B$40:B$44,'HT Cal'!B36) -> 0 | E36: =SUMIFS('HT Size'!R$40:R$44,'HT Size'!B$40:B$44,'HT Cal'!B36) -> 0 | F36: =((PI()*((D36*D36)-(E36*E36)))/4)*C36 -> 0 | G36: =SUMIFS('Materials Rate'!E$72:E$79,'Materials Rate'!B$72:B$79,'HT Cal'!B36) -> 0 | H36: =G36*F36 -> 0
A37: 5 | C37: =SUMIFS('HT Size'!H$40:H$44,'HT Size'!B$40:B$44,'HT Cal'!B37) -> 0 | D37: =SUMIFS('HT Size'!M$40:M$44,'HT Size'!B$40:B$44,'HT Cal'!B37) -> 0 | E37: =SUMIFS('HT Size'!R$40:R$44,'HT Size'!B$40:B$44,'HT Cal'!B37) -> 0 | F37: =((PI()*((D37*D37)-(E37*E37)))/4)*C37 -> 0 | G37: =SUMIFS('Materials Rate'!E$72:E$79,'Materials Rate'!B$72:B$79,'HT Cal'!B37) -> 0 | H37: =G37*F37 -> 0
A38: Total Weight : | H38: =SUM(H6:H37) -> 0

Sheet HT Size
A1: Required Raw Material Size (Input)
A3: 1. Rectangular Job
A5: Sl. No. | B5: Material | C5: Unit | D5: Length (M) | I5: Width (M) | N5: Height / Thickness (M)
D6: INCH | E6: FEET | F6: MM | G6: M | H6: INCH | I6: INCH | J6: FEET | K6: MM | L6: M | M6: INCH | N6: INCH | O6: FEET | P6: MM | Q6: M | R6: INCH
A7: 1 | B7: Heat Treatment | C7: MM | H7: =(D7*1)+(E7*12)+(F7*0.0394)+(G7*39.37) -> 0 | M7: =(I7*1)+(J7*12)+(K7*0.0394)+(L7*39.37) -> 0 | R7: =(N7*1)+(O7*12)+(P7*0.0394)+(Q7*39.37) -> 0
A8: 2 | H8: =(D8*1)+(E8*12)+(F8*0.0394)+(G8*39.37) -> 0 | M8: =(I8*1)+(J8*12)+(K8*0.0394)+(L8*39.37) -> 0 | R8: =(N8*1)+(O8*12)+(P8*0.0394)+(Q8*39.37) -> 0
A9: 3 | H9: =(D9*1)+(E9*12)+(F9*0.0394)+(G9*39.37) -> 0 | M9: =(I9*1)+(J9*12)+(K9*0.0394)+(L9*39.37) -> 0 | R9: =(N9*1)+(O9*12)+(P9*0.0394)+(Q9*39.37) -> 0
A10: 4 | H10: =(D10*1)+(E10*12)+(F10*0.0394)+(G10*39.37) -> 0 | M10: =(I10*1)+(J10*12)+(K10*0.0394)+(L10*39.37) -> 0 | R10: =(N10*1)+(O10*12)+(P10*0.0394)+(Q10*39.37) -> 0
A11: 5 | H11: =(D11*1)+(E11*12)+(F11*0.0394)+(G11*39.37) -> 0 | M11: =(I11*1)+(J11*12)+(K11*0.0394)+(L11*39.37) -> 0 | R11: =(N11*1)+(O11*12)+(P11*0.0394)+(Q11*39.37) -> 0
A14: 2. Square Job
A16: Sl. No. | B16: Material | C16: Unit | D16: Side (M) | I16: Height / Thickness (M)
D17: INCH | E17: FEET | F17: MM | G17: M | H17: INCH | I17: INCH | J17: FEET | K17: MM | L17: M | M17: INCH
A18: 1 | C18: MM | H18: =(D18*1)+(E18*12)+(F18*0.0394)+(G18*39.37) -> 0 | M18: =(I18*1)+(J18*12)+(K18*0.0394)+(L18*39.37) -> 0
A19: 2 | H19: =(D19*1)+(E19*12)+(F19*0.0394)+(G19*39.37) -> 0 | M19: =(I19*1)+(J19*12)+(K19*0.0394)+(L19*39.37) -> 0
A20: 3 | H20: =(D20*1)+(E20*12)+(F20*0.0394)+(G20*39.37) -> 0 | M20: =(I20*1)+(J20*12)+(K20*0.0394)+(L20*39.37) -> 0
A21: 4 | H21: =(D21*1)+(E21*12)+(F21*0.0394)+(G21*39.37) -> 0 | M21: =(I21*1)+(J21*12)+(K21*0.0394)+(L21*39.37) -> 0
A22: 5 | H22: =(D22*1)+(E22*12)+(F22*0.0394)+(G22*39.37) -> 0 | M22: =(I22*1)+(J22*12)+(K22*0.0394)+(L22*39.37) -> 0
A25: 3. Cylindrical Job
A27: Sl. No. | B27: Material | C27: Unit | D27: Length (M) | I27: DIA (M) | P27: INCH
D28: INCH | E28: FEET | F28: MM | G28: M | H28: INCH | I28: INCH | J28: FEET | K28: MM | L28: M | M28: INCH | P28: FEET
A29: 1 | C29: M | H29: =(D29*1)+(E29*12)+(F29*0.0394)+(G29*39.37) -> 0 | M29: =(I29*1)+(J29*12)+(K29*0.0394)+(L29*39.37) -> 0 | P29: MM
A30: 2 | H30: =(D30*1)+(E30*12)+(F30*0.0394)+(G30*39.37) -> 0 | M30: =(I30*1)+(J30*12)+(K30*0.0394)+(L30*39.37) -> 0 | P30: M
A31: 3 | H31: =(D31*1)+(E31*12)+(F31*0.0394)+(G31*39.37) -> 0 | M31: =(I31*1)+(J31*12)+(K31*0.0394)+(L31*39.37) -> 0
A32: 4 | H32: =(D32*1)+(E32*12)+(F32*0.0394)+(G32*39.37) -> 0 | M32: =(I32*1)+(J32*12)+(K32*0.0394)+(L32*39.37) -> 0
A33: 5 | H33: =(D33*1)+(E33*12)+(F33*0.0394)+(G33*39.37) -> 0 | M33: =(I33*1)+(J33*12)+(K33*0.0394)+(L33*39.37) -> 0
A36: 4. Cylindrical Hollow Job
A38: Sl. No. | B38: Material | C38: Unit | D38: Length (M) | I38: DIA-D (M) | N38: DIA-d (M)
D39: INCH | E39: FEET | F39: MM | G39: M | H39: INCH | I39: INCH | J39: FEET | K39: MM | L39: M | M39: INCH | N39: INCH | O39: FEET | P39: MM | Q39: M | R39: INCH
A40: 1 | B40: Heat Treatment | C40: INCH | H40: =(D40*1)+(E40*12)+(F40*0.0394)+(G40*39.37) -> 0 | M40: =(I40*1)+(J40*12)+(K40*0.0394)+(L40*39.37) -> 0 | R40: =(N40*1)+(O40*12)+(P40*0.0394)+(Q40*39.37) -> 0
A41: 2 | H41: =(D41*1)+(E41*12)+(F41*0.0394)+(G41*39.37) -> 0 | M41: =(I41*1)+(J41*12)+(K41*0.0394)+(L41*39.37) -> 0 | R41: =(N41*1)+(O41*12)+(P41*0.0394)+(Q41*39.37) -> 0
A42: 3 | H42: =(D42*1)+(E42*12)+(F42*0.0394)+(G42*39.37) -> 0 | M42: =(I42*1)+(J42*12)+(K42*0.0394)+(L42*39.37) -> 0 | R42: =(N42*1)+(O42*12)+(P42*0.0394)+(Q42*39.37) -> 0
A43: 4 | H43: =(D43*1)+(E43*12)+(F43*0.0394)+(G43*39.37) -> 0 | M43: =(I43*1)+(J43*12)+(K43*0.0394)+(L43*39.37) -> 0 | R43: =(N43*1)+(O43*12)+(P43*0.0394)+(Q43*39.37) -> 0
A44: 5 | H44: =(D44*1)+(E44*12)+(F44*0.0394)+(G44*39.37) -> 0 | M44: =(I44*1)+(J44*12)+(K44*0.0394)+(L44*39.37) -> 0 | R44: =(N44*1)+(O44*12)+(P44*0.0394)+(Q44*39.37) -> 0

Sheet Weight Cal
A1: Area Volume and Weight Calculation Sheet
A3: 1. Rectangular Job
A5: Sl. No. | B5: Material | C5: Length (M) | D5: Width (M) | E5: Height (M) | F5: Volume (M³) | G5: Density (kg/m³) | H5: Weight (KG)
A6: 1 | C6: =SUMIFS('Input Size'!H$7:H$11,'Input Size'!B$7:B$11,'Weight Cal'!B6) -> 0 | D6: =SUMIFS('Input Size'!M$7:M$11,'Input Size'!B$7:B$11,'Weight Cal'!B6) -> 0 | E6: =SUMIFS('Input Size'!R$7:R$11,'Input Size'!B$7:B$11,'Weight Cal'!B6) -> 0 | F6: =E6*D6*C6 -> 0 | G6: =SUMIFS(Density!C$9:C$69,Density!B$9:B$69,'Weight Cal'!B6) -> 0 | H6: =G6*F6 -> 0
A7: 2 | C7: =SUMIFS('Input Size'!H$7:H$11,'Input Size'!B$7:B$11,'Weight Cal'!B7) -> 0 | D7: =SUMIFS('Input Size'!M$7:M$11,'Input Size'!B$7:B$11,'Weight Cal'!B7) -> 0 | E7: =SUMIFS('Input Size'!R$7:R$11,'Input Size'!B$7:B$11,'Weight Cal'!B7) -> 0 | F7: =E7*D7*C7 -> 0 | G7: =SUMIFS(Density!C$9:C$69,Density!B$9:B$69,'Weight Cal'!B7) -> 0 | H7: =G7*F7 -> 0
A8: 3 | C8: =SUMIFS('Input Size'!H$7:H$11,'Input Size'!B$7:B$11,'Weight Cal'!B8) -> 0 | D8: =SUMIFS('Input Size'!M$7:M$11,'Input Size'!B$7:B$11,'Weight Cal'!B8) -> 0 | E8: =SUMIFS('Input Size'!R$7:R$11,'Input Size'!B$7:B$11,'Weight Cal'!B8) -> 0 | F8: =E8*D8*C8 -> 0 | G8: =SUMIFS(Density!C$9:C$69,Density!B$9:B$69,'Weight Cal'!B8) -> 0 | H8: =G8*F8 -> 0
A9: 4 | C9: =SUMIFS('Input Size'!H$7:H$11,'Input Size'!B$7:B$11,'Weight Cal'!B9) -> 0 | D9: =SUMIFS('Input Size'!M$7:M$11,'Input Size'!B$7:B$11,'Weight Cal'!B9) -> 0 | E9: =SUMIFS('Input Size'!R$7:R$11,'Input Size'!B$7:B$11,'Weight Cal'!B9) -> 0 | F9: =E9*D9*C9 -> 0 | G9: =SUMIFS(Density!C$9:C$69,Density!B$9:B$69,'Weight Cal'!B9) -> 0 | H9: =G9*F9 -> 0
A10: 5 | C10: =SUMIFS('Input Size'!H$7:H$11,'Input Size'!B$7:B$11,'Weight Cal'!B10) -> 0 | D10: =SUMIFS('Input Size'!M$7:M$11,'Input Size'!B$7:B$11,'Weight Cal'!B10) -> 0 | E10: =SUMIFS('Input Size'!R$7:R$11,'Input Size'!B$7:B$11,'Weight Cal'!B10) -> 0 | F10: =E10*D10*C10 -> 0 | G10: =SUMIFS(Density!C$9:C$69,Density!B$9:B$69,'Weight Cal'!B10) -> 0 | H10: =G10*F10 -> 0
A12: 2. Square Job
A14: Sl. No. | B14: Material | C14: Side (M) | D14: Height (M) | E14: Volume (M³) | F14: Density (kg/m³) | H14: Weight
A15: 1 | C15: =SUMIFS('Input Size'!H$18:H$22,'Input Size'!B$18:B$22,'Weight Cal'!B15) -> 0 | D15: =SUMIFS('Input Size'!M$18:M$22,'Input Size'!B$18:B$22,'Weight Cal'!B15) -> 0 | E15: =C15*C15*D15 -> 0 | F15: =SUMIFS(Density!C$9:C$69,Density!B$9:B$69,'Weight Cal'!B15) -> 0 | H15: =F15*E15 -> 0
A16: 2 | C16: =SUMIFS('Input Size'!H$18:H$22,'Input Size'!B$18:B$22,'Weight Cal'!B16) -> 0 | D16: =SUMIFS('Input Size'!M$18:M$22,'Input Size'!B$18:B$22,'Weight Cal'!B16) -> 0 | E16: =C16*C16*D16 -> 0 | F16: =SUMIFS(Density!C$9:C$69,Density!B$9:B$69,'Weight Cal'!B16) -> 0 | H16: =F16*E16 -> 0
A17: 3 | C17: =SUMIFS('Input Size'!H$18:H$22,'Input Size'!B$18:B$22,'Weight Cal'!B17) -> 0 | D17: =SUMIFS('Input Size'!M$18:M$22,'Input Size'!B$18:B$22,'Weight Cal'!B17) -> 0 | E17: =C17*C17*D17 -> 0 | F17: =SUMIFS(Density!C$9:C$69,Density!B$9:B$69,'Weight Cal'!B17) -> 0 | H17: =F17*E17 -> 0
A18: 4 | C18: =SUMIFS('Input Size'!H$18:H$22,'Input Size'!B$18:B$22,'Weight Cal'!B18) -> 0 | D18: =SUMIFS('Input Size'!M$18:M$22,'Input Size'!B$18:B$22,'Weight Cal'!B18) -> 0 | E18: =C18*C18*D18 -> 0 | F18: =SUMIFS(Density!C$9:C$69,Density!B$9:B$69,'Weight Cal'!B18) -> 0 | H18: =F18*E18 -> 0
A19: 5 | C19: =SUMIFS('Input Size'!H$18:H$22,'Input Size'!B$18:B$22,'Weight Cal'!B19) -> 0 | D19: =SUMIFS('Input Size'!M$18:M$22,'Input Size'!B$18:B$22,'Weight Cal'!B19) -> 0 | E19: =C19*C19*D19 -> 0 | F19: =SUMIFS(Density!C$9:C$69,Density!B$9:B$69,'Weight Cal'!B19) -> 0 | H19: =F19*E19 -> 0
A21: 3. Cylindrical Job
A23: Sl. No. | B23: Material | C23: Length (M) | D23: DIA (M) | E23: Volume (M³) | F23: Density (kg/m³) | H23: Weight
A24: 1 | C24: =SUMIFS('Input Size'!H$29:H$33,'Input Size'!B$29:B$33,'Weight Cal'!B24) -> 0 | D24: =SUMIFS('Input Size'!M$29:M$33,'Input Size'!B$29:B$33,'Weight Cal'!B24) -> 0 | E24: =((PI()*D24*D24)/4)*C24 -> 0 | F24: =SUMIFS(Density!C$9:C$69,Density!B$9:B$69,'Weight Cal'!B24) -> 0 | H24: =F24*E24 -> 0
A25: 2 | C25: =SUMIFS('Input Size'!H$29:H$33,'Input Size'!B$29:B$33,'Weight Cal'!B25) -> 0 | D25: =SUMIFS('Input Size'!M$29:M$33,'Input Size'!B$29:B$33,'Weight Cal'!B25) -> 0 | E25: =((PI()*D25*D25)/4)*C25 -> 0 | F25: =SUMIFS(Density!C$9:C$69,Density!B$9:B$69,'Weight Cal'!B25) -> 0 | H25: =F25*E25 -> 0
A26: 3 | C26: =SUMIFS('Input Size'!H$29:H$33,'Input Size'!B$29:B$33,'Weight Cal'!B26) -> 0 | D26: =SUMIFS('Input Size'!M$29:M$33,'Input Size'!B$29:B$33,'Weight Cal'!B26) -> 0 | E26: =((PI()*D26*D26)/4)*C26 -> 0 | F26: =SUMIFS(Density!C$9:C$69,Density!B$9:B$69,'Weight Cal'!B26) -> 0 | H26: =F26*E26 -> 0
A27: 4 | C27: =SUMIFS('Input Size'!H$29:H$33,'Input Size'!B$29:B$33,'Weight Cal'!B27) -> 0 | D27: =SUMIFS('Input Size'!M$29:M$33,'Input Size'!B$29:B$33,'Weight Cal'!B27) -> 0 | E27: =((PI()*D27*D27)/4)*C27 -> 0 | F27: =SUMIFS(Density!C$9:C$69,Density!B$9:B$69,'Weight Cal'!B27) -> 0 | H27: =F27*E27 -> 0
A28: 5 | C28: =SUMIFS('Input Size'!H$29:H$33,'Input Size'!B$29:B$33,'Weight Cal'!B28) -> 0 | D28: =SUMIFS('Input Size'!M$29:M$33,'Input Size'!B$29:B$33,'Weight Cal'!B28) -> 0 | E28: =((PI()*D28*D28)/4)*C28 -> 0 | F28: =SUMIFS(Density!C$9:C$69,Density!B$9:B$69,'Weight Cal'!B28) -> 0 | H28: =F28*E28 -> 0
A30: 4. Cylindrical Hollow Job
A32: Sl. No. | B32: Material | C32: Length (M) | D32: DIA-D (M) | E32: DIA-d (M) | F32: Volume (M³) | G32: Density (kg/m³) | H32: Weight
A33: 1 | C33: =SUMIFS('Input Size'!H$40:H$44,'Input Size'!B$40:B$44,'Weight Cal'!B33) -> 0 | D33: =SUMIFS('Input Size'!M$40:M$44,'Input Size'!B$40:B$44,'Weight Cal'!B33) -> 0 | E33: =SUMIFS('Input Size'!R$40:R$44,'Input Size'!B$40:B$44,'Weight Cal'!B33) -> 0 | F33: =((PI()*((D33*D33)-(E33*E33)))/4)*C33 -> 0 | G33: =SUMIFS(Density!C$9:C$69,Density!B$9:B$69,'Weight Cal'!B33) -> 0 | H33: =G33*F33 -> 0
A34: 2 | C34: =SUMIFS('Input Size'!H$40:H$44,'Input Size'!B$40:B$44,'Weight Cal'!B34) -> 0 | D34: =SUMIFS('Input Size'!M$40:M$44,'Input Size'!B$40:B$44,'Weight Cal'!B34) -> 0 | E34: =SUMIFS('Input Size'!R$40:R$44,'Input Size'!B$40:B$44,'Weight Cal'!B34) -> 0 | F34: =((PI()*((D34*D34)-(E34*E34)))/4)*C34 -> 0 | G34: =SUMIFS(Density!C$9:C$69,Density!B$9:B$69,'Weight Cal'!B34) -> 0 | H34: =G34*F34 -> 0
A35: 3 | C35: =SUMIFS('Input Size'!H$40:H$44,'Input Size'!B$40:B$44,'Weight Cal'!B35) -> 0 | D35: =SUMIFS('Input Size'!M$40:M$44,'Input Size'!B$40:B$44,'Weight Cal'!B35) -> 0 | E35: =SUMIFS('Input Size'!R$40:R$44,'Input Size'!B$40:B$44,'Weight Cal'!B35) -> 0 | F35: =((PI()*((D35*D35)-(E35*E35)))/4)*C35 -> 0 | G35: =SUMIFS(Density!C$9:C$69,Density!B$9:B$69,'Weight Cal'!B35) -> 0 | H35: =G35*F35 -> 0
A36: 4 | C36: =SUMIFS('Input Size'!H$40:H$44,'Input Size'!B$40:B$44,'Weight Cal'!B36) -> 0 | D36: =SUMIFS('Input Size'!M$40:M$44,'Input Size'!B$40:B$44,'Weight Cal'!B36) -> 0 | E36: =SUMIFS('Input Size'!R$40:R$44,'Input Size'!B$40:B$44,'Weight Cal'!B36) -> 0 | F36: =((PI()*((D36*D36)-(E36*E36)))/4)*C36 -> 0 | G36: =SUMIFS(Density!C$9:C$69,Density!B$9:B$69,'Weight Cal'!B36) -> 0 | H36: =G36*F36 -> 0
A37: 5 | C37: =SUMIFS('Input Size'!H$40:H$44,'Input Size'!B$40:B$44,'Weight Cal'!B37) -> 0 | D37: =SUMIFS('Input Size'!M$40:M$44,'Input Size'!B$40:B$44,'Weight Cal'!B37) -> 0 | E37: =SUMIFS('Input Size'!R$40:R$44,'Input Size'!B$40:B$44,'Weight Cal'!B37) -> 0 | F37: =((PI()*((D37*D37)-(E37*E37)))/4)*C37 -> 0 | G37: =SUMIFS(Density!C$9:C$69,Density!B$9:B$69,'Weight Cal'!B37) -> 0 | H37: =G37*F37 -> 0
A38: Total Weight : | H38: =SUM(H6:H37) -> 0

Sheet Input Size
A1: Required Raw Material Size (Input)
A3: 1. Rectangular Job
A5: Sl. No. | B5: Material | C5: Unit | D5: Length (M) | I5: Width (M) | N5: Height / Thickness (M)
D6: INCH | E6: FEET | F6: MM | G6: M | H6: M | I6: INCH | J6: FEET | K6: MM | L6: M | M6: M | N6: INCH | O6: FEET | P6: MM | Q6: M | R6: M
A7: 1 | C7: MM | H7: =(I7*0.0254)+(J7*0.3048)+(K7*0.001)+(L7*1) -> 0 | M7: =(I7*0.254)+(J7*0.3048)+(K7*0.001)+(L7*1) -> 0 | R7: =(N7*0.0254)+(O7*0.3048)+(P7*0.001)+(Q7*1) -> 0
A8: 2 | H8: =(D8*0.0254)+(E8*0.3048)+(F8*0.001)+(G8*1) -> 0 | M8: =(I8*0.0254)+(J8*0.3048)+(K8*0.001)+(L8*1) -> 0 | R8: =(N8*0.0254)+(O8*0.3048)+(P8*0.001)+(Q8) -> 0
A9: 3 | H9: =(D9*0.0254)+(E9*0.3048)+(F9*0.001)+(G9*1) -> 0 | M9: =(I9*0.0254)+(J9*0.3048)+(K9*0.001)+(L9*1) -> 0 | R9: =(N9*0.0254)+(O9*0.3048)+(P9*0.001)+(Q9) -> 0
A10: 4 | H10: =(D10*0.0254)+(E10*0.3048)+(F10*0.001)+(G10*1) -> 0 | M10: =(I10*0.0254)+(J10*0.3048)+(K10*0.001)+(L10*1) -> 0 | R10: =(N10*0.0254)+(O10*0.3048)+(P10*0.001)+(Q10) -> 0
A11: 5 | H11: =(D11*0.0254)+(E11*0.3048)+(F11*0.001)+(G11*1) -> 0 | M11: =(I11*0.0254)+(J11*0.3048)+(K11*0.001)+(L11*1) -> 0 | R11: =(N11*0.0254)+(O11*0.3048)+(P11*0.001)+(Q11) -> 0
A14: 2. Square Job
A16: Sl. No. | B16: Material | C16: Unit | D16: Side (M) | I16: Height / Thickness (M)
D17: INCH | E17: FEET | F17: MM | G17: M | H17: M | I17: INCH | J17: FEET | K17: MM | L17: M | M17: M
A18: 1 | C18: MM | H18: =(D18*0.0254)+(E18*0.3048)+(F18*0.001)+(G18*1) -> 0 | M18: =(I18*0.0254)+(J18*0.3048)+(K18*0.001)+(L18*1) -> 0
A19: 2 | H19: =(D19*0.0254)+(E19*0.3048)+(F19*0.001)+(G19*1) -> 0 | M19: =(I19*0.0254)+(J19*0.3048)+(K19*0.001)+(L19*1) -> 0
A20: 3 | H20: =(D20*0.0254)+(E20*0.3048)+(F20*0.001)+(G20*1) -> 0 | M20: =(I20*0.0254)+(J20*0.3048)+(K20*0.001)+(L20*1) -> 0
A21: 4 | H21: =(D21*0.0254)+(E21*0.3048)+(F21*0.001)+(G21*1) -> 0 | M21: =(I21*0.0254)+(J21*0.3048)+(K21*0.001)+(L21*1) -> 0
A22: 5 | H22: =(D22*0.0254)+(E22*0.3048)+(F22*0.001)+(G22*1) -> 0 | M22: =(I22*0.0254)+(J22*0.3048)+(K22*0.001)+(L22*1) -> 0
A25: 3. Cylindrical Job
A27: Sl. No. | B27: Material | C27: Unit | D27: Length (M) | I27: DIA (M) | P27: INCH
D28: INCH | E28: FEET | F28: MM | G28: M | H28: M | I28: INCH | J28: FEET | K28: MM | L28: M | M28: M | P28: FEET
A29: 1 | C29: MM | H29: =(D29*0.0254)+(E29*0.3048)+(F29*0.001)+(G29*1) -> 0 | M29: =(I29*0.0254)+(J29*0.3048)+(K29*0.001)+(L29*1) -> 0 | P29: MM
A30: 2 | H30: =(D30*0.0254)+(E30*0.3048)+(F30*0.001)+(G30*1) -> 0 | M30: =(I30*0.0254)+(J30*0.3048)+(K30*0.001)+(L30*1) -> 0 | P30: M
A31: 3 | H31: =(D31*0.0254)+(E31*0.3048)+(F31*0.001)+(G31*1) -> 0 | M31: =(I31*0.0254)+(J31*0.3048)+(K31*0.001)+(L31*1) -> 0
A32: 4 | H32: =(D32*0.0254)+(E32*0.3048)+(F32*0.001)+(G32*1) -> 0 | M32: =(I32*0.0254)+(J32*0.3048)+(K32*0.001)+(L32*1) -> 0
A33: 5 | H33: =(D33*0.0254)+(E33*0.3048)+(F33*0.001)+(G33*1) -> 0 | M33: =(I33*0.0254)+(J33*0.3048)+(K33*0.001)+(L33*1) -> 0
A36: 4. Cylindrical Hollow Job
A38: Sl. No. | B38: Material | C38: Unit | D38: Length (M) | I38: DIA-D (M) | N38: DIA-d (M)
D39: INCH | E39: FEET | F39: MM | G39: M | H39: M | I39: INCH | J39: FEET | K39: MM | L39: M | M39: M | N39: INCH | O39: FEET | P39: MM | Q39: M | R39: M
A40: 1 | C40: INCH | H40: =(D40*0.0254)+(E40*0.3048)+(F40*0.001)+(G40*1) -> 0 | M40: =(I40*0.0254)+(J40*0.3048)+(K40*0.001)+(L40*1) -> 0 | R40: =(N40*0.0254)+(O40*0.3048)+(P40*0.001)+(Q40*1) -> 0
A41: 2 | H41: =(D41*0.0254)+(E41*0.3048)+(F41*0.001)+(G41*1) -> 0 | M41: =(I41*0.0254)+(J41*0.3048)+(K41*0.001)+(L41*1) -> 0 | R41: =(N41*0.0254)+(O41*0.3048)+(P41*0.001)+(Q41*1) -> 0
A42: 3 | H42: =(D42*0.0254)+(E42*0.3048)+(F42*0.001)+(G42*1) -> 0 | M42: =(I42*0.0254)+(J42*0.3048)+(K42*0.001)+(L42*1) -> 0 | R42: =(N42*0.0254)+(O42*0.3048)+(P42*0.001)+(Q42*1) -> 0
A43: 4 | H43: =(D43*0.0254)+(E43*0.3048)+(F43*0.001)+(G43*1) -> 0 | M43: =(I43*0.0254)+(J43*0.3048)+(K43*0.001)+(L43*1) -> 0 | R43: =(N43*0.0254)+(O43*0.3048)+(P43*0.001)+(Q43*1) -> 0
A44: 5 | H44: =(D44*0.0254)+(E44*0.3048)+(F44*0.001)+(G44*1) -> 0 | M44: =(I44*0.0254)+(J44*0.3048)+(K44*0.001)+(L44*1) -> 0 | R44: =(N44*0.0254)+(O44*0.3048)+(P44*0.001)+(Q44*1) -> 0

Sheet Conditions
A1: Bangladesh Industrial technical Assistant Centre
A2: 116 Kha, Tejgaon I/A.
A3: Dhaka-1208
A5: Types of Cost | B5: Percentage | C5: Remarks
A6: Over Head Cost | B6: 0
B7: 10
B8: 15
B9: 20
B10: 25
B11: 30
B12: 35
B13: 40
B14: 45
B15: 50
A17: Types of Cost | B17: Percentage | C17: Remarks
A18: VAT | B18: 0
B19: 5
B20: 7.5
B21: 10
B22: 15
A24: Types of Cost | B24: Multiplies | C24: Remarks
A25: Times/ Precision | B25: 1
B26: 1.5
B27: 2
B28: 2.5
B29: 3
B30: 3.5
B31: 4
B32: 4.5
B33: 6
B34: 6.5
B35: 7
B36: 7.5
B37: 8
... B41: 10

Sheet Density
A1: Bangladesh Industrial technical Assistant Centre
A2: 116 Kha, Tejgaon I/A.
A3: Dhaka-1208
A6: Sl No | B6: Metal or Alloy | C6: Density | D6: Remarks
C8: (kg/m3)
A9: 01 | B9: Aluminum - 6061 | C9: 2720
A10: 02 | B10: Aluminum bronze (3-10% Al) | C10: 8700
A11: 03 | B11: Alloy Tool Steel | C11: 7800
A12: 04 | B12: Babbitt Metal | C12: 7272
A13: 05 | B13: Brass -60/40/rolled and drawn | C13: 8730
A14: 06 | B14: Bronze - lead | C14: 8700
A15: 07 | B15: Bronze - phosphorous | C15: 8920
A16: 08 | B16: Bronze (8-14% Sn) | C16: 8900
A17: 09 | B17: Cast Steel | C17: 7800
A18: 10 | B18: Cast iron | C18: 7800
A19: 11 | B19: Chromium | C19: 7190
A20: 12 | B20: Cobalt | C20: 8746
... A69: 61 | B69: Yellow Brass | C69: 8470

Sheet Materials Rate
A1: Bangladesh Industrial Technical Assistance Centre
A2: 116 Kha, Tejgaon I/A.
A3: Dhaka-1208
A6: Sl No | B6: Metal or Alloy | C6: Rate Tk/Kg | D6: Density | E6: Density | F6: Remarks
D8: (kg/m3) | E8: (kg/In3)
A9: 01 | B9: Aluminum - 6061 | C9: 600 | D9: 2720 | E9: =D9*(0.0254*0.0254*0.0254) -> 0.044572814
A10: 02 | B10: Aluminum bronze (3-10% Al) | C10: 2000 | D10: 8700 | E10: =D10*(0.0254*0.0254*0.0254) -> 0.14256746
A11: 03 | B11: Alloy Tool Steel | C11: 1200 | D11: 7800 | E11: =D11*(0.0254*0.0254*0.0254) -> 0.1278191
A12: 04 | B12: Babbitt Metal | C12: 5000 | D12: 7272 | E12: =D12*(0.0254*0.0254*0.0254) -> 0.11916673
A13: 05 | B13: Brass -60/40/rolled and drawn | C13: 1200 | D13: 8730 | E13: =D13*(0.0254*0.0254*0.0254) -> 0.14305907
A14: 06 | B14: Bronze - lead | C14: 2000 | D14: 8700 | E14: =D14*(0.0254*0.0254*0.0254) -> 0.14256746
A15: 07 | B15: Bronze - phosphorous | C15: 3500 | D15: 8920 | E15: =D15*(0.0254*0.0254*0.0254) -> 0.14617261
A16: 08 | B16: Bronze (8-14% Sn) | C16: 3500 | D16: 8900 | E16: =D16*(0.0254*0.0254*0.0254) -> 0.14584487
A17: 09 | B17: Cast Steel | C17: 200 | D17: 7800 | E17: =D17*(0.0254*0.0254*0.0254) -> 0.1278191
A18: 10 | B18: Cast iron | C18: 250 | D18: 7800 | E18: =D18*(0.0254*0.0254*0.0254) -> 0.1278191
A19: 11 | B19: Chromium | C19: 2000 | D19: 7190 | E19: =D19*(0.0254*0.0254*0.0254) -> 0.11782299
A20: 12 | B20: Cobalt | C20: 20000 | D20: 8746 | E20: =D20*(0.0254*0.0254*0.0254) -> 0.14332126
... A79: 70 | B79: Anneling | C79: 28 | D79: 7800 | E79: =D79*(0.0254*0.0254*0.0254) -> 0.1278191

Sheet Machining
A1: Bangladesh Industrial technical Assistant Centre
A2: 116 Kha, Tejgaon I/A.
A3: Dhaka-1208
A6: Sl No | B6: Machining Items | C6: Group A | D6: Group B | E6: Group C | F6: Remarks
C7: For Small & Cottege Industry | D7: For Corp. Multinational & Large Industries | E7: For Import Substitute
A8: 01 | B8: Heavy Duity Lathe | C8: 200 | D8: 250 | E8: 300
A9: 02 | B9: Medium & Precision Lathe | C9: 150 | D9: 180 | E9: 220
A10: 03 | B10: Heavy Duity Milling | C10: 250 | D10: 300 | E10: 420
A11: 04 | B11: Medium & Precision Milling | C11: 200 | D11: 250 | E11: 300
A12: 05 | B12: Cylindrical Grinding | C12: 300 | D12: 380 | E12: 450
A13: 06 | B13: Polishing | C13: 300 | D13: 380 | E13: 450
A14: 07 | B14: Centerless Grinding | C14: 600 | D14: 750 | E14: 900
A15: 08 | B15: Tool Grinding | C15: 500 | D15: 630 | E15: 750
A16: 09 | B16: Jig Grinding | C16: 600 | D16: 750 | E16: 900
A17: 10 | B17: Drill | C17: 100 | D17: 120 | E17: 150
A18: 11 | B18: Radial Drill | C18: 200 | D18: 250 | E18: 300
A19: 12 | B19: Shaper | C19: 150 | D19: 180 | E19: 220
... A39: 32 | B39: Die & Mold Fitting Work | C39: 400 | D39: 500 | E39: 600
A40: 33 | B40: Pattern Cost | C40: 80 | D40: 100 | E40: 120 | F40: N/A
A41: 34 | B41: C.I Casting Simple | C41: 200 | D41: 250 | E41: 300 | F41: N/A
A42: 35 | B42: C.I Casting Complex | C42: 300 | D42: 400 | E42: 500 | F42: N/A
A43: 36 | B43: Alloy C.I Low Alloy | C43: 150 | D43: 200 | E43: 250 | F43: N/A
A44: 37 | B44: Alloy C.I High Alloy | C44: 180 | D44: 250 | E44: 300 | F44: N/A
A45: 38 | B45: Gun Metal Casting | C45: 1500 | D45: 2000 | E45: 2500 | F45: N/A
A46: 39 | B46: P/Al Bronze Casting | C46: 2000 | D46: 2500 | E46: 2800 | F46: N/A
A47: 40 | B47: Al Casting | C47: 550 | D47: 650 | E47: 750 | F47: N/A
A48: 41 | B48: White Metalling Tin Base | C48: 4000 | D48: 4500 | E48: 5000 | F48: N/A
A49: 42 | B49: White Metalling Lead Base | C49: 600 | D49: 800 | E49: 1100 | F49: N/A
A50: 43 | B50: Bright Crome Plating | C50: 20 | D50: 25 | E50: 30 | F50: N/A
A51: 44 | B51: Hard Crome Palting | C51: 50 | D51: 60 | E51: 70 | F51: N/A
... A62: 55 | B62: Embossing (Replica) | C62: 650 | D62: 750 | E62: 850 | F62: N/A
A63: 56 | B63: Embossing Machine | C63: 30000 | D63: 30000 | E63: 30000
A64: 57 | B64: Percution Machine | C64: 40000 | D64: 40000 | E64: 40000 | F64: N/A
A65: 58 | B65: Signature Die | C65: 5500 | D65: 5500 | E65: 5500 | F65: N/A
A66: 59 | B66: EDM | C66: 800 | D66: 900 | E66: 1000 | F66: N/A
A67: 60 | B67: Wire Cut | C67: 800 | D67: 900 | E67: 1000 | F67: N/A
A68: 61 | B68: VMC | C68: 800 | D68: 900 | E68: 1000 | F68: N/A
A69: 62 | B69: Letter Inserting | C69: 450 | D69: 500 | E69: 550 | F69: N/A
A70: 63 | B70: Number Incerting | C70: 450 | D70: 500 | E70: 550 | F70: N/A
A71: 64 | B71: Medel Embossing | C71: 450 | D71: 500 | E71: 550 | F71: N/A
